Workbook

Sheet Tổng quan
A2: DEEP LEARNING
A3: Phân loại 8 loại trái cây và trạng thái fresh/spoiled | Thực hiện 01/10-10/10/2026 | Thuyết trình 11/10/2026 | Cập nhật 03/10/2026
A6: Tổng nhiệm vụ | D6: Đã hoàn thành | G6: Tiến độ trung bình | J6: KPI đã tick
A7: =COUNTA('Kế hoạch 10 ngày'!$A$6:$A$78) -> 73 | D7: =COUNTIF('Kế hoạch 10 ngày'!$K$6:$K$78,"Hoàn thành") -> 38 | G7: =IFERROR(AVERAGE('Kế hoạch 10 ngày'!$M$6:$M$78),0) -> 0.64109589 | J7: =IFERROR(COUNTIF('Kế hoạch 10 ngày'!$J$6:$J$78,"☑")/COUNTA('Kế hoạch 10 ngày'!$A$6:$A$78),0) -> 0.52054795
A10: Phân công trách nhiệm chính
A11: Thành viên | B11: Vai trò | C11: Trách nhiệm kỹ thuật | D11: Nội dung báo cáo và bàn giao | I11: Hạng mục | J11: Deliverable | K11: Owner | L11: Hạng mục | M11: Deliverable | N11: Owner
A12: Trình | B12: Trưởng nhóm và tích hợp | C12: Quản lý tiến độ, repository, môi trường, kiểm định rò rỉ dữ liệu, metrics, đánh giá, tích hợp | D12: Lý thuyết CNN (Phần 1), mô tả bài toán, kết quả thực nghiệm, tổng hợp báo cáo, Q&A | I12: Báo cáo | J12: final/Major_Assignment_Report.docx | K12: Trình | L12: Slide | M12: final/Presentation.pptx | N12: Hiếu
A13: Tùng | B13: Data và Model 1 | C13: Tải và kiểm định dataset, làm sạch, chia tập chống rò rỉ, pipeline, augmentation, Simple CNN, demo | D13: Mô tả dataset, tiền xử lý dữ liệu, Model 1 và demo | I13: Source code | J13: src/ + scripts/ (repository) | K13: Cả nhóm | L13: Notebook demo | M13: notebooks/05_demo_prediction.ipynb | N13: Tùng
A14: Quân | B14: Model 2 | C14: Multi-task CNN: shared trunk khối phần dư, fruit head, freshness head, loss weights, ablation Model 2 | D14: Học đa nhiệm và kết quả Model 2 | I14: Model 1 | J14: models/model1_simple_cnn.keras | K14: Tùng | L14: Model 2 | M14: models/model2_multitask_cnn.keras | N14: Quân
A15: Hiếu | B15: Model 3 và trực quan | C15: MobileNetV2 transfer learning, fine-tuning, ablation số lớp, Grad-CAM, hình, sơ đồ kiến trúc, slide | D15: Transfer learning, kết quả Model 3, Grad-CAM và slide | I15: Model 3 | J15: models/model3_mobilenet_v2.keras | K15: Hiếu | L15: Metrics | M15: reports/final_metrics.csv | N15: Trình
I16: Hình kết quả | J16: figures/ | K16: Hiếu | L16: README | M16: README.md | N16: Trình
A17: Mốc tiến độ theo ngày | I17: Demo | J17: demo/demo_images/ | K17: Tùng | L17: Script | M17: docs/presentation_script.md | N17: Trình
A18: Ngày | B18: Trọng tâm | C18: Lead | D18: Milestone và deliverable chính | E18: Tiến độ | F18: KPI đạt | G18: Trạng thái | I18: Q&A | J18: docs/qa_preparation.md | K18: Cả nhóm | L18: Bài nộp | M18: final/submission.zip | N18: Trình
A19: 46296.208 | B19: Khởi động | C19: Trình | D19: Khóa phạm vi, repository, môi trường và khung báo cáo | E19: =IFERROR(SUMIF('Kế hoạch 10 ngày'!$B$6:$B$78,A19,'Kế hoạch 10 ngày'!$M$6:$M$78)/COUNTIF('Kế hoạch 10 ngày'!$B$6:$B$78,A19),0) -> 1 | F19: =IFERROR(COUNTIFS('Kế hoạch 10 ngày'!$B$6:$B$78,A19,'Kế hoạch 10 ngày'!$J$6:$J$78,"☑")/COUNTIF('Kế hoạch 10 ngày'!$B$6:$B$78,A19),0) -> 1 | G19: =IF(E19=1,"Hoàn thành",IF(E19>0,"Đang thực hiện","Chưa bắt đầu")) -> Hoàn thành | I19: Dữ liệu | J19: data/metadata.csv; data/splits/ | K19: Tùng | L19: Log | M19: reports/experiment_log.csv | N19: Trình
A20: 46297.208 | B20: Dữ liệu | C20: Tùng | D20: Data audit: 1.273 ảnh trùng + 1 ảnh sai nhãn; Dataset Description | E20: =IFERROR(SUMIF('Kế hoạch 10 ngày'!$B$6:$B$78,A20,'Kế hoạch 10 ngày'!$M$6:$M$78)/COUNTIF('Kế hoạch 10 ngày'!$B$6:$B$78,A20),0) -> 1 | F20: =IFERROR(COUNTIFS('Kế hoạch 10 ngày'!$B$6:$B$78,A20,'Kế hoạch 10 ngày'!$J$6:$J$78,"☑")/COUNTIF('Kế hoạch 10 ngày'!$B$6:$B$78,A20),0) -> 1 | G20: =IF(E20=1,"Hoàn thành",IF(E20>0,"Đang thực hiện","Chưa bắt đầu")) -> Hoàn thành | I20: Kiến trúc | J20: figures/model_*_architecture.png | K20: Hiếu | L20: So sánh | M20: tables/model_comparison.xlsx | N20: Trình
A21: 46298.208 | B21: Tiền xử lý | C21: Tùng | D21: Khóa split chống rò rỉ (70/15/15) và pipeline dữ liệu chung | E21: =IFERROR(SUMIF('Kế hoạch 10 ngày'!$B$6:$B$78,A21,'Kế hoạch 10 ngày'!$M$6:$M$78)/COUNTIF('Kế hoạch 10 ngày'!$B$6:$B$78,A21),0) -> 1 | F21: =IFERROR(COUNTIFS('Kế hoạch 10 ngày'!$B$6:$B$78,A21,'Kế hoạch 10 ngày'!$J$6:$J$78,"☑")/COUNTIF('Kế hoạch 10 ngày'!$B$6:$B$78,A21),0) -> 1 | G21: =IF(E21=1,"Hoàn thành",IF(E21>0,"Đang thực hiện","Chưa bắt đầu")) -> Hoàn thành | I21: Nguồn dataset | J21: Mendeley Data | K21: Tùng | L21: Ngày thuyết trình | M21: 46306.208 | N21: Cả nhóm
A22: 46299.208 | B22: Xây dựng model | C22: Tùng; Quân; Hiếu | D22: Ba model compile và smoke test thành công | E22: =IFERROR(SUMIF('Kế hoạch 10 ngày'!$B$6:$B$78,A22,'Kế hoạch 10 ngày'!$M$6:$M$78)/COUNTIF('Kế hoạch 10 ngày'!$B$6:$B$78,A22),0) -> 1 | F22: =IFERROR(COUNTIFS('Kế hoạch 10 ngày'!$B$6:$B$78,A22,'Kế hoạch 10 ngày'!$J$6:$J$78,"☑")/COUNTIF('Kế hoạch 10 ngày'!$B$6:$B$78,A22),0) -> 1 | G22: =IF(E22=1,"Hoàn thành",IF(E22>0,"Đang thực hiện","Chưa bắt đầu")) -> Hoàn thành
A23: 46300.208 | B23: Baseline | C23: Cả nhóm | D23: Model summary, sơ đồ kiến trúc và script huấn luyện | E23: =IFERROR(SUMIF('Kế hoạch 10 ngày'!$B$6:$B$78,A23,'Kế hoạch 10 ngày'!$M$6:$M$78)/COUNTIF('Kế hoạch 10 ngày'!$B$6:$B$78,A23),0) -> 0.91666667 | F23: =IFERROR(COUNTIFS('Kế hoạch 10 ngày'!$B$6:$B$78,A23,'Kế hoạch 10 ngày'!$J$6:$J$78,"☑")/COUNTIF('Kế hoạch 10 ngày'!$B$6:$B$78,A23),0) -> 0.83333333 | G23: =IF(E23=1,"Hoàn thành",IF(E23>0,"Đang thực hiện","Chưa bắt đầu")) -> Đang thực hiện | I23: Cách sử dụng tracker
A24: 46301.208 | B24: Huấn luyện | C24: Tùng; Quân; Hiếu | D24: Checkpoint và history của ba model | E24: =IFERROR(SUMIF('Kế hoạch 10 ngày'!$B$6:$B$78,A24,'Kế hoạch 10 ngày'!$M$6:$M$78)/COUNTIF('Kế hoạch 10 ngày'!$B$6:$B$78,A24),0) -> 0.5 | F24: =IFERROR(COUNTIFS('Kế hoạch 10 ngày'!$B$6:$B$78,A24,'Kế hoạch 10 ngày'!$J$6:$J$78,"☑")/COUNTIF('Kế hoạch 10 ngày'!$B$6:$B$78,A24),0) -> 0.2 | G24: =IF(E24=1,"Hoàn thành",IF(E24>0,"Đang thực hiện","Chưa bắt đầu")) -> Đang thực hiện | I24: 1. Chọn trạng thái trong dropdown ở cột K. Tiến độ cột M sẽ tự cập nhật.
A25: 46302.208 | B25: Phân tích lỗi | C25: Cả nhóm | D25: Ablation, phân tích lỗi, Grad-CAM; khóa hyperparameters | E25: =IFERROR(SUMIF('Kế hoạch 10 ngày'!$B$6:$B$78,A25,'Kế hoạch 10 ngày'!$M$6:$M$78)/COUNTIF('Kế hoạch 10 ngày'!$B$6:$B$78,A25),0) -> 0.2 | F25: =IFERROR(COUNTIFS('Kế hoạch 10 ngày'!$B$6:$B$78,A25,'Kế hoạch 10 ngày'!$J$6:$J$78,"☑")/COUNTIF('Kế hoạch 10 ngày'!$B$6:$B$78,A25),0) -> 0.1 | G25: =IF(E25=1,"Hoàn thành",IF(E25>0,"Đang thực hiện","Chưa bắt đầu")) -> Đang thực hiện | I25: 2. Khi KPI của nhiệm vụ đã đạt, đổi ô ở cột J từ ☐ thành ☑.
A26: 46303.208 | B26: Huấn luyện cuối | C26: Tùng; Quân; Hiếu | D26: Khóa ba final checkpoints | E26: =IFERROR(SUMIF('Kế hoạch 10 ngày'!$B$6:$B$78,A26,'Kế hoạch 10 ngày'!$M$6:$M$78)/COUNTIF('Kế hoạch 10 ngày'!$B$6:$B$78,A26),0) -> 0 | F26: =IFERROR(COUNTIFS('Kế hoạch 10 ngày'!$B$6:$B$78,A26,'Kế hoạch 10 ngày'!$J$6:$J$78,"☑")/COUNTIF('Kế hoạch 10 ngày'!$B$6:$B$78,A26),0) -> 0 | G26: =IF(E26=1,"Hoàn thành",IF(E26>0,"Đang thực hiện","Chưa bắt đầu")) -> Chưa bắt đầu | I26: 3. Chỉ đánh dấu Hoàn thành khi deliverable tồn tại và KPI đã được kiểm tra.
A27: 46304.208 | B27: Đánh giá | C27: Trình | D27: Khóa metrics, bảng so sánh và nội dung kết quả | E27: =IFERROR(SUMIF('Kế hoạch 10 ngày'!$B$6:$B$78,A27,'Kế hoạch 10 ngày'!$M$6:$M$78)/COUNTIF('Kế hoạch 10 ngày'!$B$6:$B$78,A27),0) -> 0.47777778 | F27: =IFERROR(COUNTIFS('Kế hoạch 10 ngày'!$B$6:$B$78,A27,'Kế hoạch 10 ngày'!$J$6:$J$78,"☑")/COUNTIF('Kế hoạch 10 ngày'!$B$6:$B$78,A27),0) -> 0 | G27: =IF(E27=1,"Hoàn thành",IF(E27>0,"Đang thực hiện","Chưa bắt đầu")) -> Đang thực hiện | I27: 4. Trạng thái Bị vướng cần ghi nguyên nhân và hành động tiếp theo ở cột N.
A28: 46305.208 | B28: Hoàn thiện | C28: Cả nhóm | D28: Khóa báo cáo, slide, demo và submission.zip | E28: =IFERROR(SUMIF('Kế hoạch 10 ngày'!$B$6:$B$78,A28,'Kế hoạch 10 ngày'!$M$6:$M$78)/COUNTIF('Kế hoạch 10 ngày'!$B$6:$B$78,A28),0) -> 0.16666667 | F28: =IFERROR(COUNTIFS('Kế hoạch 10 ngày'!$B$6:$B$78,A28,'Kế hoạch 10 ngày'!$J$6:$J$78,"☑")/COUNTIF('Kế hoạch 10 ngày'!$B$6:$B$78,A28),0) -> 0 | G28: =IF(E28=1,"Hoàn thành",IF(E28>0,"Đang thực hiện","Chưa bắt đầu")) -> Đang thực hiện | I28: 5. Ngày 08/10 khóa model, ngày 09/10 khóa kết quả, ngày 10/10 khóa bài nộp.
A31: Nguồn dataset: https://data.mendeley.com/datasets/6ps7gtp2wg/1 | DOI: 10.17632/6ps7gtp2wg.1

Sheet Kế hoạch 10 ngày
A2: BẢNG PHÂN CHIA CÔNG VIỆC 01/10-10/10/2026
A3: Cập nhật trạng thái bằng dropdown, tick KPI khi điều kiện hoàn thành đã được kiểm tra. Tiến độ được tính tự động từ trạng thái.
A5: STT | B5: Ngày | C5: Giai đoạn | D5: Công việc | E5: Phụ trách | F5: Phối hợp | G5: Output | H5: Deliverable | I5: KPI / Điều kiện hoàn thành | J5: Check KPI | K5: Trạng thái | L5: Ưu tiên | M5: Tiến độ | N5: Ghi chú / Vướng mắc
A6: 1 | B6: 46296.208 | C6: Khởi động | D6: Chốt bài toán nhận diện loại trái cây và tình trạng fresh/spoiled | E6: Trình | F6: Cả nhóm | G6: Phạm vi, input, output, lớp dương tính (spoiled) | H6: docs/problem_definition.md | I6: Có đủ input, output, 8 loại quả và 2 trạng thái | J6: ☑ | K6: Hoàn thành | L6: Cao | M6: =IF(K6="Hoàn thành",1,IF(K6="Chờ kiểm tra",0.8,IF(K6="Đang thực hiện",0.5,IF(K6="Bị vướng",0.25,0)))) -> 1
A7: 2 | B7: 46296.208 | C7: Khởi động | D7: Chốt thiết kế Model 1: Simple Sequential CNN dự đoán 16 lớp | E7: Tùng | F7: Trình | G7: Kiến trúc 5 khối Conv-ReLU-MaxPool + FC | H7: docs/model_plan.md | I7: Có block CNN, classifier và output 16 lớp | J7: ☑ | K7: Hoàn thành | L7: Cao | M7: =IF(K7="Hoàn thành",1,IF(K7="Chờ kiểm tra",0.8,IF(K7="Đang thực hiện",0.5,IF(K7="Bị vướng",0.25,0)))) -> 1 | N7: 3,75 triệu tham số
A8: 3 | B8: 46296.208 | C8: Khởi động | D8: Chốt thiết kế Model 2: shared trunk khối phần dư và hai output head | E8: Quân | F8: Trình | G8: Kiến trúc multi-task được mô tả | H8: docs/model_plan.md | I8: Fruit head 8 lớp và freshness head nhị phân | J8: ☑ | K8: Hoàn thành | L8: Cao | M8: =IF(K8="Hoàn thành",1,IF(K8="Chờ kiểm tra",0.8,IF(K8="Đang thực hiện",0.5,IF(K8="Bị vướng",0.25,0)))) -> 1 | N8: Thân kiểu ResNet-10, 4,99 triệu tham số
A9: 4 | B9: 46296.208 | C9: Khởi động | D9: Chốt Model 3: MobileNetV2 (ImageNet) và kế hoạch fine-tuning 2 giai đoạn | E9: Hiếu | F9: Trình | G9: Backbone và phạm vi fine-tuning được chọn | H9: docs/model_plan.md | I9: Nêu rõ frozen stage và fine-tuning stage | J9: ☑ | K9: Hoàn thành | L9: Cao | M9: =IF(K9="Hoàn thành",1,IF(K9="Chờ kiểm tra",0.8,IF(K9="Đang thực hiện",0.5,IF(K9="Bị vướng",0.25,0)))) -> 1 | N9: Mở băng từ block_13_expand
A10: 5 | B10: 46296.208 | C10: Khởi động | D10: Tạo cấu trúc repository và quy ước đặt tên file | E10: Trình | F10: Cả nhóm | G10: Cấu trúc src, scripts, configs, data, reports, figures, docs, tests | H10: Repository + .gitignore | I10: Có cấu trúc thư mục; slides/ không đưa lên Git | J10: ☑ | K10: Hoàn thành | L10: Cao | M10: =IF(K10="Hoàn thành",1,IF(K10="Chờ kiểm tra",0.8,IF(K10="Đang thực hiện",0.5,IF(K10="Bị vướng",0.25,0)))) -> 1 | N10: Push GitHub sau khi nhóm duyệt (việc 72)
A11: 6 | B11: 46296.208 | C11: Khởi động | D11: Tạo môi trường TensorFlow/Keras dùng chung | E11: Trình | F11: Tùng | G11: Python 3.12, TensorFlow 2.21, Keras 3.15 | H11: requirements.txt | I11: Cài đặt sạch và import không lỗi | J11: ☑ | K11: Hoàn thành | L11: Cao | M11: =IF(K11="Hoàn thành",1,IF(K11="Chờ kiểm tra",0.8,IF(K11="Đang thực hiện",0.5,IF(K11="Bị vướng",0.25,0)))) -> 1 | N11: TensorFlow trên Windows chạy CPU
A12: 7 | B12: 46296.208 | C12: Khởi động | D12: Tạo khung báo cáo theo mẫu giảng viên (tiếng Việt) | E12: Trình | F12: Cả nhóm | G12: Bìa, mục lục, Phần 1, Phần 2, tài liệu tham khảo | H12: report/; report/build_report.py | I12: Đủ toàn bộ heading bắt buộc, xuất được Word | J12: ☑ | K12: Hoàn thành | L12: Trung bình | M12: =IF(K12="Hoàn thành",1,IF(K12="Chờ kiểm tra",0.8,IF(K12="Đang thực hiện",0.5,IF(K12="Bị vướng",0.25,0)))) -> 1 | N12: Build tự động Markdown -> Word/PDF
A13: 8 | B13: 46297.208 | C13: Dữ liệu | D13: Tải và giải nén dataset từ Mendeley | E13: Tùng | F13: Trình | G13: Dataset FRUIT-16K sẵn sàng để đọc | H13: scripts/download_data.py; data/raw/ | I13: Tải đủ 16 thư mục x 1.000 ảnh, ghi lại nguồn | J13: ☑ | K13: Hoàn thành | L13: Cao | M13: =IF(K13="Hoàn thành",1,IF(K13="Chờ kiểm tra",0.8,IF(K13="Đang thực hiện",0.5,IF(K13="Bị vướng",0.25,0)))) -> 1 | N13: 16.000 ảnh, CC BY 4.0, ~100 MB
A14: 9 | B14: 46297.208 | C14: Dữ liệu | D14: Kiểm tra cấu trúc thư mục và ánh xạ nhãn | E14: Tùng | F14: Quân | G14: Bản đồ thư mục -> fruit, freshness, combined label | H14: reports/data_structure.txt | I14: Mọi thư mục được ánh xạ đúng nhãn | J14: ☑ | K14: Hoàn thành | L14: Cao | M14: =IF(K14="Hoàn thành",1,IF(K14="Chờ kiểm tra",0.8,IF(K14="Đang thực hiện",0.5,IF(K14="Bị vướng",0.25,0)))) -> 1
A15: 10 | B15: 46297.208 | C15: Dữ liệu | D15: Thống kê số ảnh theo loại quả, trạng thái và lớp kết hợp | E15: Tùng | F15: Trình | G15: Bảng phân bố lớp thực tế | H15: reports/class_distribution.csv | I15: Tổng ảnh khớp số ảnh đọc được | J15: ☑ | K15: Hoàn thành | L15: Cao | M15: =IF(K15="Hoàn thành",1,IF(K15="Chờ kiểm tra",0.8,IF(K15="Đang thực hiện",0.5,IF(K15="Bị vướng",0.25,0)))) -> 1
A16: 11 | B16: 46297.208 | C16: Dữ liệu | D16: Kiểm tra ảnh lỗi, ảnh không đọc được và sai định dạng | E16: Tùng | F16: Trình | G16: Danh sách tệp có vấn đề | H16: reports/data_quality_report.csv | I16: 100% ảnh được thử đọc | J16: ☑ | K16: Hoàn thành | L16: Cao | M16: =IF(K16="Hoàn thành",1,IF(K16="Chờ kiểm tra",0.8,IF(K16="Đang thực hiện",0.5,IF(K16="Bị vướng",0.25,0)))) -> 1 | N16: 0 ảnh lỗi; tất cả 224x224 RGB
A17: 12 | B17: 46297.208 | C17: Dữ liệu | D17: Thống kê kích thước, tỉ lệ khung hình, kênh màu, mean/std | E17: Trình | F17: Tùng | G17: Thống kê kỹ thuật của ảnh | H17: reports/image_statistics.csv | I17: Có min, max và kích thước phổ biến | J17: ☑ | K17: Hoàn thành | L17: Trung bình | M17: =IF(K17="Hoàn thành",1,IF(K17="Chờ kiểm tra",0.8,IF(K17="Đang thực hiện",0.5,IF(K17="Bị vướng",0.25,0)))) -> 1
A18: 13 | B18: 46297.208 | C18: Dữ liệu | D18: Phát hiện ảnh trùng lặp (SHA-256) và ảnh gán nhãn mâu thuẫn (pHash) | E18: Tùng | F18: Trình | G18: Danh sách ảnh trùng và ảnh sai nhãn | H18: reports/duplicate_groups.csv; reports/label_conflicts.csv | I18: Mọi ảnh được băm và so khớp | J18: ☑ | K18: Hoàn thành | L18: Cao | M18: =IF(K18="Hoàn thành",1,IF(K18="Chờ kiểm tra",0.8,IF(K18="Đang thực hiện",0.5,IF(K18="Bị vướng",0.25,0)))) -> 1 | N18: 1.273 ảnh trùng + 1 ảnh sai nhãn -> loại bỏ
A19: 14 | B19: 46297.208 | C19: Dữ liệu | D19: Tạo lưới ảnh mẫu 16 lớp và hình minh hoạ ảnh trùng | E19: Hiếu | F19: Tùng | G19: Hình minh hoạ dataset | H19: figures/dataset_samples.png; figures/duplicate_examples.png | I19: Mỗi lớp có ít nhất một ảnh đại diện | J19: ☑ | K19: Hoàn thành | L19: Trung bình | M19: =IF(K19="Hoàn thành",1,IF(K19="Chờ kiểm tra",0.8,IF(K19="Đang thực hiện",0.5,IF(K19="Bị vướng",0.25,0)))) -> 1
A20: 15 | B20: 46297.208 | C20: Dữ liệu | D20: Viết Dataset Description cho báo cáo | E20: Tùng | F20: Trình | G20: Mục II của báo cáo | H20: report/part2_bai_toan_du_lieu_mo_hinh.md | I20: Có link, số ảnh, lớp, kích thước và giấy phép | J20: ☑ | K20: Hoàn thành | L20: Trung bình | M20: =IF(K20="Hoàn thành",1,IF(K20="Chờ kiểm tra",0.8,IF(K20="Đang thực hiện",0.5,IF(K20="Bị vướng",0.25,0)))) -> 1
A21: 16 | B21: 46298.208 | C21: Tiền xử lý | D21: Tạo metadata cho từng ảnh | E21: Tùng | F21: Trình | G21: Path, nhãn, hash, quyết định làm sạch, nhóm, tập | H21: data/metadata.csv | I21: Không thiếu path hoặc nhãn | J21: ☑ | K21: Hoàn thành | L21: Cao | M21: =IF(K21="Hoàn thành",1,IF(K21="Chờ kiểm tra",0.8,IF(K21="Đang thực hiện",0.5,IF(K21="Bị vướng",0.25,0)))) -> 1
A22: 17 | B22: 46298.208 | C22: Tiền xử lý | D22: Chia train/val/test phân tầng, chống rò rỉ dữ liệu theo nhóm ảnh | E22: Tùng | F22: Trình | G22: Ba tập dữ liệu cố định 70/15/15 | H22: data/splits/train.csv; val.csv; test.csv | I22: Phân bố 16 lớp lệch không quá 1,3 điểm % | J22: ☑ | K22: Hoàn thành | L22: Cao | M22: =IF(K22="Hoàn thành",1,IF(K22="Chờ kiểm tra",0.8,IF(K22="Đang thực hiện",0.5,IF(K22="Bị vướng",0.25,0)))) -> 1 | N22: 10.320 / 2.203 / 2.203 ảnh
A23: 18 | B23: 46298.208 | C23: Tiền xử lý | D23: Audit data leakage và ảnh trùng giữa các tập | E23: Trình | F23: Tùng | G23: Báo cáo split sạch, so sánh với chia ngẫu nhiên | H23: reports/split_audit.txt; reports/leakage_comparison.csv | I23: Không có path, hash hoặc nhóm trùng giữa các tập | J23: ☑ | K23: Hoàn thành | L23: Cao | M23: =IF(K23="Hoàn thành",1,IF(K23="Chờ kiểm tra",0.8,IF(K23="Đang thực hiện",0.5,IF(K23="Bị vướng",0.25,0)))) -> 1 | N23: Ảnh test có bản sao gần giống: 9,7% -> 1,2%
A24: 19 | B24: 46298.208 | C24: Tiền xử lý | D24: Cài đặt resize và normalization (chuẩn hoá trong model) | E24: Tùng | F24: Hiếu | G24: Input 224x224x3; [0,1] hoặc [-1,1] cho MobileNetV2 | H24: src/data_pipeline.py | I24: Batch có shape và miền giá trị đúng | J24: ☑ | K24: Hoàn thành | L24: Cao | M24: =IF(K24="Hoàn thành",1,IF(K24="Chờ kiểm tra",0.8,IF(K24="Đang thực hiện",0.5,IF(K24="Bị vướng",0.25,0)))) -> 1
A25: 20 | B25: 46298.208 | C25: Tiền xử lý | D25: Cài đặt data augmentation chỉ cho training set | E25: Tùng | F25: Quân | G25: Flip, rotation, zoom, brightness, contrast | H25: src/data_pipeline.py | I25: Validation và test không bị augmentation | J25: ☑ | K25: Hoàn thành | L25: Cao | M25: =IF(K25="Hoàn thành",1,IF(K25="Chờ kiểm tra",0.8,IF(K25="Đang thực hiện",0.5,IF(K25="Bị vướng",0.25,0)))) -> 1
A26: 21 | B26: 46298.208 | C26: Tiền xử lý | D26: Tạo tf.data pipeline dùng chung cho ba model | E26: Tùng | F26: Trình | G26: Data loader có cache, shuffle, batch, prefetch | H26: src/data_pipeline.py | I26: Ba model nhận cùng split dữ liệu | J26: ☑ | K26: Hoàn thành | L26: Cao | M26: =IF(K26="Hoàn thành",1,IF(K26="Chờ kiểm tra",0.8,IF(K26="Đang thực hiện",0.5,IF(K26="Bị vướng",0.25,0)))) -> 1
A27: 22 | B27: 46298.208 | C27: Tiền xử lý | D27: Kiểm thử batch ảnh, nhãn và trực quan hoá augmentation | E27: Trình | F27: Tùng | G27: Notebook xác nhận pipeline | H27: notebooks/01_data_validation.ipynb | I27: Ảnh và ba dạng nhãn khớp nhau | J27: ☑ | K27: Hoàn thành | L27: Trung bình | M27: =IF(K27="Hoàn thành",1,IF(K27="Chờ kiểm tra",0.8,IF(K27="Đang thực hiện",0.5,IF(K27="Bị vướng",0.25,0)))) -> 1 | N27: Notebook chạy không lỗi
A28: 23 | B28: 46298.208 | C28: Tiền xử lý | D28: Vẽ hình phân bố lớp, so sánh rò rỉ và augmentation | E28: Hiếu | F28: Tùng | G28: Hình cho báo cáo và slide | H28: figures/class_distribution.png; split_leakage.png; augmentation_examples.png | I28: Hình đọc được, có chú thích | J28: ☑ | K28: Hoàn thành | L28: Trung bình | M28: =IF(K28="Hoàn thành",1,IF(K28="Chờ kiểm tra",0.8,IF(K28="Đang thực hiện",0.5,IF(K28="Bị vướng",0.25,0)))) -> 1
A29: 24 | B29: 46298.208 | C29: Tiền xử lý | D29: Viết mục Tiền xử lý dữ liệu cho báo cáo | E29: Tùng | F29: Trình | G29: Mục III.1 của báo cáo | H29: report/part2_bai_toan_du_lieu_mo_hinh.md | I29: Có số mẫu của từng tập | J29: ☑ | K29: Hoàn thành | L29: Trung bình | M29: =IF(K29="Hoàn thành",1,IF(K29="Chờ kiểm tra",0.8,IF(K29="Đang thực hiện",0.5,IF(K29="Bị vướng",0.25,0)))) -> 1
A30: 25 | B30: 46299.208 | C30: Xây dựng model | D30: Xây dựng Model 1 bằng Keras Sequential API | E30: Tùng | F30: Trình | G30: Simple CNN chạy forward pass | H30: src/models/simple_cnn.py | I30: Output shape bằng 16 | J30: ☑ | K30: Hoàn thành | L30: Cao | M30: =IF(K30="Hoàn thành",1,IF(K30="Chờ kiểm tra",0.8,IF(K30="Đang thực hiện",0.5,IF(K30="Bị vướng",0.25,0)))) -> 1
A31: 26 | B31: 46299.208 | C31: Xây dựng model | D31: Xây dựng shared trunk khối phần dư cho Model 2 | E31: Quân | F31: Tùng | G31: Feature extractor CNN dùng chung | H31: src/models/multitask_cnn.py | I31: Trunk trả về feature map hợp lệ | J31: ☑ | K31: Hoàn thành | L31: Cao | M31: =IF(K31="Hoàn thành",1,IF(K31="Chờ kiểm tra",0.8,IF(K31="Đang thực hiện",0.5,IF(K31="Bị vướng",0.25,0)))) -> 1
A32: 27 | B32: 46299.208 | C32: Xây dựng model | D32: Xây dựng hai output head (dùng chung cho Model 2 và 3) | E32: Quân | F32: Hiếu | G32: Fruit softmax và freshness sigmoid | H32: src/models/heads.py | I32: Hai output có shape 8 và 1 | J32: ☑ | K32: Hoàn thành | L32: Cao | M32: =IF(K32="Hoàn thành",1,IF(K32="Chờ kiểm tra",0.8,IF(K32="Đang thực hiện",0.5,IF(K32="Bị vướng",0.25,0)))) -> 1
A33: 28 | B33: 46299.208 | C33: Xây dựng model | D33: Xây dựng Model 3 với MobileNetV2 pretrained | E33: Hiếu | F33: Trình | G33: Transfer model chạy forward pass | H33: src/models/transfer_model.py | I33: Backbone tải đúng ImageNet weights | J33: ☑ | K33: Hoàn thành | L33: Cao | M33: =IF(K33="Hoàn thành",1,IF(K33="Chờ kiểm tra",0.8,IF(K33="Đang thực hiện",0.5,IF(K33="Bị vướng",0.25,0)))) -> 1
A34: 29 | B34: 46299.208 | C34: Xây dựng model | D34: Cấu hình loss, optimizer, loss weights và callbacks | E34: Tùng | F34: Quân; Hiếu | G34: Cấu hình compile và huấn luyện cho ba model | H34: configs/training_config.json; src/training/callbacks.py | I34: Loss khớp từng loại output | J34: ☑ | K34: Hoàn thành | L34: Cao | M34: =IF(K34="Hoàn thành",1,IF(K34="Chờ kiểm tra",0.8,IF(K34="Đang thực hiện",0.5,IF(K34="Bị vướng",0.25,0)))) -> 1
A35: 30 | B35: 46299.208 | C35: Xây dựng model | D35: Cài đặt metrics chung để so sánh công bằng | E35: Trình | F35: Quân | G35: Fruit, freshness và joint metrics | H35: src/evaluation/metrics.py | I35: Model 1 được giải mã từ 16 lớp về hai nhãn | J35: ☑ | K35: Hoàn thành | L35: Cao | M35: =IF(K35="Hoàn thành",1,IF(K35="Chờ kiểm tra",0.8,IF(K35="Đang thực hiện",0.5,IF(K35="Bị vướng",0.25,0)))) -> 1
A36: 31 | B36: 46299.208 | C36: Xây dựng model | D36: Smoke test ba model và pipeline | E36: Cả nhóm | F36: Trình | G36: Ba model train một batch không lỗi | H36: tests/test_models.py; tests/test_data_pipeline.py | I36: Không lỗi shape, dtype hoặc loss | J36: ☑ | K36: Hoàn thành | L36: Cao | M36: =IF(K36="Hoàn thành",1,IF(K36="Chờ kiểm tra",0.8,IF(K36="Đang thực hiện",0.5,IF(K36="Bị vướng",0.25,0)))) -> 1 | N36: 12/12 test pass
A37: 32 | B37: 46300.208 | C37: Baseline | D37: Xuất model summary và số lượng tham số | E37: Trình | F37: Tùng; Quân; Hiếu | G37: Bảng layer và parameters | H37: reports/model_summaries/; reports/model_parameters.csv | I37: Có trainable và non-trainable parameters | J37: ☑ | K37: Hoàn thành | L37: Trung bình | M37: =IF(K37="Hoàn thành",1,IF(K37="Chờ kiểm tra",0.8,IF(K37="Đang thực hiện",0.5,IF(K37="Bị vướng",0.25,0)))) -> 1
A38: 33 | B38: 46300.208 | C38: Baseline | D38: Vẽ kiến trúc Model 1 | E38: Tùng | F38: Hiếu | G38: Sơ đồ CNN tuần tự | H38: figures/model_1_architecture.png | I38: Thể hiện input, blocks và output | J38: ☑ | K38: Hoàn thành | L38: Trung bình | M38: =IF(K38="Hoàn thành",1,IF(K38="Chờ kiểm tra",0.8,IF(K38="Đang thực hiện",0.5,IF(K38="Bị vướng",0.25,0)))) -> 1
A39: 34 | B39: 46300.208 | C39: Baseline | D39: Vẽ kiến trúc Model 2 | E39: Quân | F39: Hiếu | G39: Sơ đồ shared trunk, khối phần dư và hai nhánh | H39: figures/model_2_architecture.png | I39: Hai output head thể hiện rõ | J39: ☑ | K39: Hoàn thành | L39: Trung bình | M39: =IF(K39="Hoàn thành",1,IF(K39="Chờ kiểm tra",0.8,IF(K39="Đang thực hiện",0.5,IF(K39="Bị vướng",0.25,0)))) -> 1
A40: 35 | B40: 46300.208 | C40: Baseline | D40: Vẽ kiến trúc Model 3 | E40: Hiếu | F40: Trình | G40: Sơ đồ backbone và hai nhánh | H40: figures/model_3_architecture.png | I40: Phân biệt frozen và trainable layers | J40: ☑ | K40: Hoàn thành | L40: Trung bình | M40: =IF(K40="Hoàn thành",1,IF(K40="Chờ kiểm tra",0.8,IF(K40="Đang thực hiện",0.5,IF(K40="Bị vướng",0.25,0)))) -> 1
A41: 36 | B41: 46300.208 | C41: Baseline | D41: Viết script huấn luyện và chạy toàn bộ thí nghiệm | E41: Trình | F41: Cả nhóm | G41: train.py cho 3 model, run_experiments.py cho mọi run | H41: scripts/train.py; scripts/run_experiments.py | I41: Chạy lại toàn bộ bằng một lệnh | J41: ☑ | K41: Hoàn thành | L41: Cao | M41: =IF(K41="Hoàn thành",1,IF(K41="Chờ kiểm tra",0.8,IF(K41="Đang thực hiện",0.5,IF(K41="Bị vướng",0.25,0)))) -> 1
A42: 37 | B42: 46300.208 | C42: Baseline | D42: Đánh giá thời gian mỗi epoch và bộ nhớ | E42: Trình | F42: Cả nhóm | G42: Bảng chi phí tính toán sơ bộ | H42: reports/resource_report.md | I42: Có thời gian, CPU và batch size | J42: ☐ | K42: Đang thực hiện | L42: Trung bình | M42: =IF(K42="Hoàn thành",1,IF(K42="Chờ kiểm tra",0.8,IF(K42="Đang thực hiện",0.5,IF(K42="Bị vướng",0.25,0)))) -> 0.5 | N42: Đo lại khi CPU rảnh (sau khi train xong)
...
